<sdf version='1.7'>
  <world name='default'>
    <physics type='ode'>
      <max_step_size>0.0002</max_step_size>
      <real_time_factor>1</real_time_factor>
      <real_time_update_rate>5000</real_time_update_rate>
      <ode>
        <solver>
          <type>quick</type>
          <iters>50</iters>
          <sor>1.3</sor>
          <use_dynamic_moi_rescaling>0</use_dynamic_moi_rescaling>
        </solver>
        <constraints>
          <cfm>0</cfm>
          <erp>0.2</erp>
          <contact_max_correcting_vel>10</contact_max_correcting_vel>
          <contact_surface_layer>0.001</contact_surface_layer>
        </constraints>
      </ode>
    </physics>
    <scene>
      <sky>
        <clouds>
          <speed>12</speed>
        </clouds>
      </sky>
      <ambient>0.4 0.4 0.4 1</ambient>
      <background>0.7 0.7 0.7 1</background>
      <shadows>1</shadows>
    </scene>
    <light name='sun' type='directional'>
      <cast_shadows>1</cast_shadows>
      <pose>0 0 10 0 -0 0</pose>
      <diffuse>0.8 0.8 0.8 1</diffuse>
      <specular>0.2 0.2 0.2 1</specular>
      <attenuation>
        <range>1000</range>
        <constant>0.9</constant>
        <linear>0.01</linear>
        <quadratic>0.001</quadratic>
      </attenuation>
      <direction>-0.5 0.1 -0.9</direction>
      <spot>
        <inner_angle>0</inner_angle>
        <outer_angle>0</outer_angle>
        <falloff>0</falloff>
      </spot>
    </light>
    <model name='ground_plane'>
      <static>1</static>
      <link name='link'>
        <collision name='collision'>
          <geometry>
            <plane>
              <normal>0 0 1</normal>
              <size>100 100</size>
            </plane>
          </geometry>
          <surface>
            <contact>
              <collide_bitmask>65535</collide_bitmask>
              <ode/>
            </contact>
            <friction>
              <ode>
                <mu>100</mu>
                <mu2>50</mu2>
              </ode>
              <torsional>
                <ode/>
              </torsional>
            </friction>
            <bounce/>
          </surface>
          <max_contacts>10</max_contacts>
        </collision>
        <visual name='visual'>
          <cast_shadows>0</cast_shadows>
          <geometry>
            <plane>
              <normal>0 0 1</normal>
              <size>100 100</size>
            </plane>
          </geometry>
          <material>
            <script>
              <uri>file://media/materials/scripts/gazebo.material</uri>
              <name>Gazebo/Grey</name>
            </script>
          </material>
        </visual>
        <self_collide>0</self_collide>
        <enable_wind>0</enable_wind>
        <kinematic>0</kinematic>
      </link>
    </model>
    <model name='static_environment'>
      <static>1</static>
      <link name='static_box'>
        <pose>-2 2 0.5 0 -0 0</pose>
        <collision name='static_box_collision'>
          <geometry>
            <box>
              <size>1 1 1</size>
            </box>
          </geometry>
          <max_contacts>10</max_contacts>
          <surface>
            <contact>
              <ode/>
            </contact>
            <bounce/>
            <friction>
              <torsional>
                <ode/>
              </torsional>
              <ode/>
            </friction>
          </surface>
        </collision>
        <visual name='static_box_visual'>
          <geometry>
            <box>
              <size>1 1 1</size>
            </box>
          </geometry>
          <material>
            <ambient>0.2 0.2 0.2 1</ambient>
            <diffuse>0.421 0.225 0 1</diffuse>
          </material>
        </visual>
        <self_collide>0</self_collide>
        <enable_wind>0</enable_wind>
        <kinematic>0</kinematic>
      </link>
    </model>
    <gravity>0 0 -9.81</gravity>
    <magnetic_field>6e-06 2.3e-05 -4.2e-05</magnetic_field>
    <atmosphere type='adiabatic'/>
    <wind/>
    <spherical_coordinates>
      <surface_model>EARTH_WGS84</surface_model>
      <latitude_deg>0</latitude_deg>
      <longitude_deg>0</longitude_deg>
      <elevation>0</elevation>
      <heading_deg>0</heading_deg>
    </spherical_coordinates>
    <state world_name='default'>
      <sim_time>144 492400000</sim_time>
      <real_time>29 744917796</real_time>
      <wall_time>1699371001 740572424</wall_time>
      <iterations>135663</iterations>
      <model name='a1_gazebo'>
        <pose>0.012799 0.037856 0.055706 -0.000627 0.001068 0.007061</pose>
        <scale>1 1 1</scale>
        <link name='FL_calf'>
          <pose>0.012057 0.200075 0.019264 1.57829 -1.07242 -1.57285</pose>
          <velocity>0.001286 0.031999 -0.007535 0.826846 0.066713 -0.000281</velocity>
          <acceleration>-0.448016 0.926713 2.59681 2.64956 1.34594 -3.08515</acceleration>
          <wrench>-0.094531 0.195536 0.547926 0 -0 0</wrench>
        </link>
        <link name='FL_hip'>
          <pose>0.192963 0.086129 0.055484 0.498374 0.001068 0.00706</pose>
          <velocity>0.003391 0.001987 -0.113446 0.824159 0.064888 -0.000475</velocity>
          <acceleration>-0.508593 0.52203 1.6359 0.993451 0.177957 1.28461</acceleration>
          <wrench>-0.302613 0.310608 0.973363 0 -0 0</wrench>
        </link>
        <link name='FL_thigh'>
          <pose>0.192486 0.159734 0.09554 0.897357 0.912841 0.787708</pose>
          <velocity>0.006213 -0.031066 -0.052655 0.823773 0.065391 -0.000219</velocity>
          <acceleration>-0.959231 0.185926 2.00104 -1.03166 0.240686 2.23607</acceleration>
          <wrench>-0.851797 0.165102 1.77692 0 -0 0</wrench>
        </link>
        <link name='FR_calf'>
          <pose>0.014343 -0.124334 0.019271 -1.57821 -1.07292 1.58688</pose>
          <velocity>0.001197 -0.026553 -0.006399 -0.792881 0.062268 -0.002031</velocity>
          <acceleration>12.6506 -40.9544 -49.5766 -0.330052 -0.979515 -2.65556</acceleration>
          <wrench>2.66928 -8.64137 -10.4607 0 -0 0</wrench>
        </link>
        <link name='FR_hip'>
          <pose>0.193627 -0.007869 0.055543 -0.497854 0.001067 0.007061</pose>
          <velocity>0.003413 0.002011 -0.110228 -0.79616 0.054005 0.001976</velocity>
          <acceleration>-0.289265 0.633859 2.51015 -1.90978 -0.667883 -3.04689</acceleration>
          <wrench>-0.172113 0.377146 1.49354 0 -0 0</wrench>
        </link>
        <link name='FR_thigh'>
          <pose>0.194189 -0.081494 0.095561 -0.896803 0.913239 -0.773175</pose>
          <velocity>0.005825 0.033922 -0.051505 -0.796018 0.061198 -0.001641</velocity>
          <acceleration>0.930455 2.19634 8.69362 -1.00719 -0.96116 2.15808</acceleration>
          <wrench>0.826244 1.95035 7.71994 0 -0 0</wrench>
        </link>
        <link name='RL_calf'>
          <pose>-0.348934 0.197402 0.019261 1.57836 -1.07578 -1.5729</pose>
          <velocity>0.001268 0.026227 -0.005373 0.653263 0.065873 -0.001533</velocity>
          <acceleration>6.00523 24.2305 -27.7961 -2.27376 0.392551 -1.62014</acceleration>
          <wrench>1.2671 5.11264 -5.86498 0 -0 0</wrench>
        </link>
        <link name='RL_hip'>
          <pose>-0.168028 0.08358 0.055869 0.494994 0.001067 0.007062</pose>
          <velocity>0.00342 0.001955 -0.092051 0.656351 0.064522 -0.002014</velocity>
          <acceleration>-0.383275 0.221799 -0.528337 1.27578 0.777712 0.905081</acceleration>
          <wrench>-0.228049 0.13197 -0.314361 0 -0 0</wrench>
        </link>
        <link name='RL_thigh'>
          <pose>-0.168506 0.15732 0.095677 0.893419 0.915218 0.784597</pose>
          <velocity>0.006185 -0.024202 -0.043529 0.656033 0.065596 -0.001522</velocity>
          <acceleration>0.19993 -1.23304 4.2737 -1.06523 1.53123 2.80364</acceleration>
          <wrench>0.177538 -1.09494 3.79505 0 -0 0</wrench>
        </link>
        <link name='RR_calf'>
          <pose>-0.34665 -0.126758 0.019268 -1.57826 -1.07631 1.58691</pose>
          <velocity>0.001172 -0.021361 -0.00376 -0.635987 0.060786 -0.000528</velocity>
          <acceleration>-0.194701 0.189198 0.148888 -0.708353 -0.490306 -1.28306</acceleration>
          <wrench>-0.041082 0.039921 0.031415 0 -0 0</wrench>
        </link>
        <link name='RR_hip'>
          <pose>-0.167364 -0.010418 0.055928 -0.494465 0.001068 0.007061</pose>
          <velocity>0.003403 0.001983 -0.08884 -0.638635 0.054284 0.000224</velocity>
          <acceleration>-0.382675 0.343464 -0.02428 1.25023 -0.654567 -0.727528</acceleration>
          <wrench>-0.227692 0.204361 -0.014446 0 -0 0</wrench>
        </link>
        <link name='RR_thigh'>
          <pose>-0.166801 -0.084178 0.095697 -0.892861 0.915626 -0.770062</pose>
          <velocity>0.005706 0.027383 -0.041755 -0.638736 0.060178 -0.000371</velocity>
          <acceleration>-0.504855 0.427968 -0.027825 0.059936 -0.534482 0.854268</acceleration>
          <wrench>-0.448311 0.380036 -0.024709 0 -0 0</wrench>
        </link>
        <link name='base'>
          <pose>0.012799 0.037856 0.055706 -0.000627 0.001068 0.007061</pose>
          <velocity>0.003378 0.001977 -0.101146 -0.034694 0.059157 1.7e-05</velocity>
          <acceleration>-0.389507 0.392156 0.771248 -0.814369 -0.307125 0.050325</acceleration>
          <wrench>-2.33743 2.35333 4.62826 0 -0 0</wrench>
        </link>
      </model>
      <model name='ground_plane'>
        <pose>0 0 0 0 -0 0</pose>
        <scale>1 1 1</scale>
        <link name='link'>
          <pose>0 0 0 0 -0 0</pose>
          <velocity>0 0 0 0 -0 0</velocity>
          <acceleration>0 0 0 0 -0 0</acceleration>
          <wrench>0 0 0 0 -0 0</wrench>
        </link>
      </model>
      <model name='static_environment'>
        <pose>0 0 0 0 -0 0</pose>
        <scale>1 1 1</scale>
        <link name='static_box'>
          <pose>-2 2 0.5 0 -0 0</pose>
          <velocity>0 0 0 0 -0 0</velocity>
          <acceleration>0 0 0 0 -0 0</acceleration>
          <wrench>0 0 0 0 -0 0</wrench>
        </link>
      </model>
      <model name='unit_box'>
        <pose>2.09215 0.004722 -0.84 0 -0.150001 0</pose>
        <scale>1 1 1</scale>
        <link name='link'>
          <pose>2.09215 0.004722 -0.84 0 -0.150001 0</pose>
          <velocity>0 0 0 0 -0 0</velocity>
          <acceleration>0 0 0 0 -0 0</acceleration>
          <wrench>0 0 0 0 -0 0</wrench>
        </link>
      </model>
      <light name='sun'>
        <pose>0 0 10 0 -0 0</pose>
      </light>
    </state>
    <gui fullscreen='0'>
      <camera name='user_camera'>
        <pose>1.50532 -4.94806 1.33491 0 0.145714 1.61482</pose>
        <view_controller>orbit</view_controller>
        <projection_type>perspective</projection_type>
      </camera>
    </gui>
    <model name='a1_gazebo'>
      <link name='base'>
        <inertial>
          <pose>0 0.004099 -0.0005 0 -0 0</pose>
          <mass>6.001</mass>
          <inertia>
            <ixx>0.0159533</ixx>
            <ixy>-3.66e-05</ixy>
            <ixz>-6.11e-05</ixz>
            <iyy>0.0378999</iyy>
            <iyz>-2.7498e-05</iyz>
            <izz>0.0457542</izz>
          </inertia>
        </inertial>
        <collision name='base_fixed_joint_lump__trunk_collision'>
          <pose>0 0 0 0 -0 0</pose>
          <geometry>
            <box>
              <size>0.267 0.194 0.114</size>
            </box>
          </geometry>
          <surface>
            <contact>
              <ode>
                <kp>1e+06</kp>
                <kd>1</kd>
              </ode>
            </contact>
            <friction>
              <ode>
                <mu>0.2</mu>
                <mu2>0.2</mu2>
              </ode>
              <torsional>
                <ode/>
              </torsional>
            </friction>
            <bounce/>
          </surface>
          <max_contacts>10</max_contacts>
        </collision>
        <collision name='base_fixed_joint_lump__imu_link_collision_1'>
          <pose>0 0 0 0 -0 0</pose>
          <geometry>
            <box>
              <size>0.001 0.001 0.001</size>
            </box>
          </geometry>
          <surface>
            <contact>
              <ode/>
            </contact>
            <friction>
              <ode>
                <mu>0.2</mu>
                <mu2>0.2</mu2>
              </ode>
              <torsional>
                <ode/>
              </torsional>
            </friction>
            <bounce/>
          </surface>
          <max_contacts>10</max_contacts>
        </collision>
        <visual name='base_visual'>
          <pose>0 0 0 0 -0 0</pose>
          <geometry>
            <box>
              <size>0.001 0.001 0.001</size>
            </box>
          </geometry>
          <material>
            <script>
              <name>Gazebo/Green</name>
              <uri>file://media/materials/scripts/gazebo.material</uri>
            </script>
          </material>
        </visual>
        <visual name='base_fixed_joint_lump__trunk_visual_1'>
          <pose>0 0 0 0 -0 0</pose>
          <geometry>
            <mesh>
              <scale>1 1 1</scale>
              <uri>/home/crp/git/quad_sys/src/a1_description/meshes/trunk.dae</uri>
            </mesh>
          </geometry>
        </visual>
        <visual name='base_fixed_joint_lump__imu_link_visual_2'>
          <pose>0 0 0 0 -0 0</pose>
          <geometry>
            <box>
              <size>0.001 0.001 0.001</size>
            </box>
          </geometry>
          <material>
            <script>
              <name>Gazebo/Red</name>
              <uri>file://media/materials/scripts/gazebo.material</uri>
            </script>
          </material>
        </visual>
        <gravity>1</gravity>
        <gravity>1</gravity>
        <sensor name='imu_sensor' type='imu'>
          <always_on>1</always_on>
          <update_rate>1000</update_rate>
          <visualize>1</visualize>
          <topic>__default_topic__</topic>
          <plugin name='imu_plugin' filename='libgazebo_ros_imu_sensor.so'>
            <topicName>trunk_imu</topicName>
            <bodyName>imu_link</bodyName>
            <updateRateHZ>1000.0</updateRateHZ>
            <gaussianNoise>0.0</gaussianNoise>
            <xyzOffset>0 0 0</xyzOffset>
            <rpyOffset>0 0 0</rpyOffset>
            <frameName>imu_link</frameName>
            <robotNamespace>/</robotNamespace>
          </plugin>
          <pose>0 0 0 0 -0 0</pose>
          <imu/>
        </sensor>
        <self_collide>0</self_collide>
        <enable_wind>0</enable_wind>
        <kinematic>0</kinematic>
      </link>
      <joint name='FL_hip_joint' type='revolute'>
        <pose relative_to='base'>0.1805 0.047 0 0 -0 0</pose>
        <parent>base</parent>
        <child>FL_hip</child>
        <axis>
          <xyz>1 0 0</xyz>
          <limit>
            <lower>-0.802851</lower>
            <upper>0.802851</upper>
            <effort>33.5</effort>
            <velocity>21</velocity>
          </limit>
          <dynamics>
            <damping>0</damping>
            <friction>0</friction>
            <spring_reference>0</spring_reference>
            <spring_stiffness>0</spring_stiffness>
          </dynamics>
        </axis>
      </joint>
      <link name='FL_hip'>
        <pose relative_to='FL_hip_joint'>0 0 0 0 -0 0</pose>
        <inertial>
          <pose>-0.003875 0.001622 4.2e-05 0 -0 0</pose>
          <mass>0.595</mass>
          <inertia>
            <ixx>0.000402747</ixx>
            <ixy>-8.709e-06</ixy>
            <ixz>-2.97e-07</ixz>
            <iyy>0.000691123</iyy>
            <iyz>-5.45e-07</iyz>
            <izz>0.000487919</izz>
          </inertia>
        </inertial>
        <collision name='FL_hip_collision'>
          <pose>0 0 0 1.5708 -0 0</pose>
          <geometry>
            <cylinder>
              <length>0.04</length>
              <radius>0.046</radius>
            </cylinder>
          </geometry>
          <surface>
            <contact>
              <ode/>
            </contact>
            <friction>
              <ode>
                <mu>0.2</mu>
                <mu2>0.2</mu2>
              </ode>
              <torsional>
                <ode/>
              </torsional>
            </friction>
            <bounce/>
          </surface>
          <max_contacts>10</max_contacts>
        </collision>
        <collision name='FL_hip_fixed_joint_lump__FL_thigh_shoulder_collision_1'>
          <pose>0 0.081 0 1.5708 -0 0</pose>
          <geometry>
            <cylinder>
              <length>0.032</length>
              <radius>0.041</radius>
            </cylinder>
          </geometry>
          <max_contacts>10</max_contacts>
          <surface>
            <contact>
              <ode/>
            </contact>
            <bounce/>
            <friction>
              <torsional>
                <ode/>
              </torsional>
              <ode/>
            </friction>
          </surface>
        </collision>
        <visual name='FL_hip_visual'>
          <pose>0 0 0 0 -0 0</pose>
          <geometry>
            <mesh>
              <scale>1 1 1</scale>
              <uri>/home/crp/git/quad_sys/src/a1_description/meshes/hip.dae</uri>
            </mesh>
          </geometry>
          <material>
            <script>
              <name>Gazebo/DarkGrey</name>
              <uri>file://media/materials/scripts/gazebo.material</uri>
            </script>
          </material>
        </visual>
        <self_collide>0</self_collide>
        <enable_wind>0</enable_wind>
        <kinematic>0</kinematic>
      </link>
      <joint name='FL_thigh_joint' type='revolute'>
        <pose relative_to='FL_hip'>0 0.0838 0 0 -0 0</pose>
        <parent>FL_hip</parent>
        <child>FL_thigh</child>
        <axis>
          <xyz>0 1 0</xyz>
          <limit>
            <lower>-1.0472</lower>
            <upper>4.18879</upper>
            <effort>33.5</effort>
            <velocity>21</velocity>
          </limit>
          <dynamics>
            <damping>0</damping>
            <friction>0</friction>
            <spring_reference>0</spring_reference>
            <spring_stiffness>0</spring_stiffness>
          </dynamics>
        </axis>
      </joint>
      <link name='FL_thigh'>
        <pose relative_to='FL_thigh_joint'>0 0 0 0 -0 0</pose>
        <inertial>
          <pose>-0.003574 -0.019529 -0.030323 0 -0 0</pose>
          <mass>0.888</mass>
          <inertia>
            <ixx>0.00525181</ixx>
            <ixy>-2.168e-06</ixy>
            <ixz>0.000346889</ixz>
            <iyy>0.00500047</iyy>
            <iyz>-2.8174e-05</iyz>
            <izz>0.0011102</izz>
          </inertia>
        </inertial>
        <collision name='FL_thigh_collision'>
          <pose>0 0 -0.1 3.14159 1.57079 3.14159</pose>
          <geometry>
            <box>
              <size>0.2 0.0245 0.034</size>
            </box>
          </geometry>
          <surface>
            <contact>
              <ode>
                <kp>1e+06</kp>
                <kd>1</kd>
              </ode>
            </contact>
            <friction>
              <ode>
                <mu>0.2</mu>
                <mu2>0.2</mu2>
              </ode>
              <torsional>
                <ode/>
              </torsional>
            </friction>
            <bounce/>
          </surface>
          <max_contacts>10</max_contacts>
        </collision>
        <visual name='FL_thigh_visual'>
          <pose>0 0 0 0 -0 0</pose>
          <geometry>
            <mesh>
              <scale>1 1 1</scale>
              <uri>/home/crp/git/quad_sys/src/a1_description/meshes/thigh.dae</uri>
            </mesh>
          </geometry>
          <material>
            <script>
              <name>Gazebo/DarkGrey</name>
              <uri>file://media/materials/scripts/gazebo.material</uri>
            </script>
          </material>
        </visual>
        <self_collide>1</self_collide>
        <enable_wind>0</enable_wind>
        <kinematic>0</kinematic>
      </link>
      <joint name='FL_calf_joint' type='revolute'>
        <pose relative_to='FL_thigh'>0 0 -0.2 0 -0 0</pose>
        <parent>FL_thigh</parent>
        <child>FL_calf</child>
        <axis>
          <xyz>0 1 0</xyz>
          <limit>
            <lower>-2.69653</lower>
            <upper>-0.916298</upper>
            <effort>33.5</effort>
            <velocity>21</velocity>
          </limit>
          <dynamics>
            <damping>0</damping>
            <friction>0</friction>
            <spring_reference>0</spring_reference>
            <spring_stiffness>0</spring_stiffness>
          </dynamics>
        </axis>
      </joint>
      <link name='FL_calf'>
        <pose relative_to='FL_calf_joint'>0 0 0 0 -0 0</pose>
        <inertial>
          <pose>0.005085 -0.000171 -0.126241 0 -0 0</pose>
          <mass>0.211</mass>
          <inertia>
            <ixx>0.00281049</ixx>
            <ixy>7.29135e-08</ixy>
            <ixz>-0.000172718</ixz>
            <iyy>0.00282865</iyy>
            <iyz>1.0577e-06</iyz>
            <izz>4.2928e-05</izz>
          </inertia>
        </inertial>
        <collision name='FL_calf_collision'>
          <pose>0 0 -0.1 3.14159 1.57079 3.14159</pose>
          <geometry>
            <box>
              <size>0.2 0.016 0.016</size>
            </box>
          </geometry>
          <surface>
            <contact>
              <ode/>
            </contact>
            <friction>
              <ode>
                <mu>0.2</mu>
                <mu2>0.2</mu2>
              </ode>
              <torsional>
                <ode/>
              </torsional>
            </friction>
            <bounce/>
          </surface>
          <max_contacts>10</max_contacts>
        </collision>
        <collision name='FL_calf_fixed_joint_lump__FL_foot_collision_1'>
          <pose>0 0 -0.2 0 -0 0</pose>
          <geometry>
            <sphere>
              <radius>0.02</radius>
            </sphere>
          </geometry>
          <surface>
            <contact>
              <ode>
                <kp>1e+06</kp>
                <kd>1</kd>
              </ode>
            </contact>
            <friction>
              <ode>
                <mu>0.6</mu>
                <mu2>0.6</mu2>
              </ode>
              <torsional>
                <ode/>
              </torsional>
            </friction>
            <bounce/>
          </surface>
          <max_contacts>10</max_contacts>
        </collision>
        <visual name='FL_calf_visual'>
          <pose>0 0 0 0 -0 0</pose>
          <geometry>
            <mesh>
              <scale>1 1 1</scale>
              <uri>/home/crp/git/quad_sys/src/a1_description/meshes/calf.dae</uri>
            </mesh>
          </geometry>
        </visual>
        <visual name='FL_calf_fixed_joint_lump__FL_foot_visual_1'>
          <pose>0 0 -0.2 0 -0 0</pose>
          <geometry>
            <sphere>
              <radius>0.01</radius>
            </sphere>
          </geometry>
          <plugin name='drawForcePlugin' filename='libunitreeDrawForcePlugin.so'>
            <topicName>FL_foot_contact</topicName>
            <robotNamespace>/</robotNamespace>
          </plugin>
          <material>
            <script>
              <name>Gazebo/DarkGrey</name>
              <uri>file://media/materials/scripts/gazebo.material</uri>
            </script>
          </material>
        </visual>
        <sensor name='FL_foot_contact' type='contact'>
          <update_rate>100</update_rate>
          <plugin name='contactPlugin' filename='libunitreeFootContactPlugin.so'>
            <robotNamespace>/</robotNamespace>
          </plugin>
          <contact>
            <collision>FL_calf_fixed_joint_lump__FL_foot_collision_1</collision>
            <topic>__default_topic__</topic>
          </contact>
        </sensor>
        <self_collide>1</self_collide>
        <self_collide>1</self_collide>
        <enable_wind>0</enable_wind>
        <kinematic>0</kinematic>
      </link>
      <joint name='FR_hip_joint' type='revolute'>
        <pose relative_to='base'>0.1805 -0.047 0 0 -0 0</pose>
        <parent>base</parent>
        <child>FR_hip</child>
        <axis>
          <xyz>1 0 0</xyz>
          <limit>
            <lower>-0.802851</lower>
            <upper>0.802851</upper>
            <effort>33.5</effort>
            <velocity>21</velocity>
          </limit>
          <dynamics>
            <damping>0</damping>
            <friction>0</friction>
            <spring_reference>0</spring_reference>
            <spring_stiffness>0</spring_stiffness>
          </dynamics>
        </axis>
      </joint>
      <link name='FR_hip'>
        <pose relative_to='FR_hip_joint'>0 0 0 0 -0 0</pose>
        <inertial>
          <pose>-0.003875 -0.001622 4.2e-05 0 -0 0</pose>
          <mass>0.595</mass>
          <inertia>
            <ixx>0.000402747</ixx>
            <ixy>8.709e-06</ixy>
            <ixz>-2.97e-07</ixz>
            <iyy>0.000691123</iyy>
            <iyz>5.45e-07</iyz>
            <izz>0.000487919</izz>
          </inertia>
        </inertial>
        <collision name='FR_hip_collision'>
          <pose>0 0 0 1.5708 -0 0</pose>
          <geometry>
            <cylinder>
              <length>0.04</length>
              <radius>0.046</radius>
            </cylinder>
          </geometry>
          <surface>
            <contact>
              <ode/>
            </contact>
            <friction>
              <ode>
                <mu>0.2</mu>
                <mu2>0.2</mu2>
              </ode>
              <torsional>
                <ode/>
              </torsional>
            </friction>
            <bounce/>
          </surface>
          <max_contacts>10</max_contacts>
        </collision>
        <collision name='FR_hip_fixed_joint_lump__FR_thigh_shoulder_collision_1'>
          <pose>0 -0.081 0 1.5708 -0 0</pose>
          <geometry>
            <cylinder>
              <length>0.032</length>
              <radius>0.041</radius>
            </cylinder>
          </geometry>
          <max_contacts>10</max_contacts>
          <surface>
            <contact>
              <ode/>
            </contact>
            <bounce/>
            <friction>
              <torsional>
                <ode/>
              </torsional>
              <ode/>
            </friction>
          </surface>
        </collision>
        <visual name='FR_hip_visual'>
          <pose>0 0 0 3.14159 -0 0</pose>
          <geometry>
            <mesh>
              <scale>1 1 1</scale>
              <uri>/home/crp/git/quad_sys/src/a1_description/meshes/hip.dae</uri>
            </mesh>
          </geometry>
          <material>
            <script>
              <name>Gazebo/DarkGrey</name>
              <uri>file://media/materials/scripts/gazebo.material</uri>
            </script>
          </material>
        </visual>
        <self_collide>0</self_collide>
        <enable_wind>0</enable_wind>
        <kinematic>0</kinematic>
      </link>
      <joint name='FR_thigh_joint' type='revolute'>
        <pose relative_to='FR_hip'>0 -0.0838 0 0 -0 0</pose>
        <parent>FR_hip</parent>
        <child>FR_thigh</child>
        <axis>
          <xyz>0 1 0</xyz>
          <limit>
            <lower>-1.0472</lower>
            <upper>4.18879</upper>
            <effort>33.5</effort>
            <velocity>21</velocity>
          </limit>
          <dynamics>
            <damping>0</damping>
            <friction>0</friction>
            <spring_reference>0</spring_reference>
            <spring_stiffness>0</spring_stiffness>
          </dynamics>
        </axis>
      </joint>
      <link name='FR_thigh'>
        <pose relative_to='FR_thigh_joint'>0 0 0 0 -0 0</pose>
        <inertial>
          <pose>-0.003574 0.019529 -0.030323 0 -0 0</pose>
          <mass>0.888</mass>
          <inertia>
            <ixx>0.00525181</ixx>
            <ixy>2.168e-06</ixy>
            <ixz>0.000346889</ixz>
            <iyy>0.00500047</iyy>
            <iyz>2.8174e-05</iyz>
            <izz>0.0011102</izz>
          </inertia>
        </inertial>
        <collision name='FR_thigh_collision'>
          <pose>0 0 -0.1 3.14159 1.57079 3.14159</pose>
          <geometry>
            <box>
              <size>0.2 0.0245 0.034</size>
            </box>
          </geometry>
          <surface>
            <contact>
              <ode>
                <kp>1e+06</kp>
                <kd>1</kd>
              </ode>
            </contact>
            <friction>
              <ode>
                <mu>0.2</mu>
                <mu2>0.2</mu2>
              </ode>
              <torsional>
                <ode/>
              </torsional>
            </friction>
            <bounce/>
          </surface>
          <max_contacts>10</max_contacts>
        </collision>
        <visual name='FR_thigh_visual'>
          <pose>0 0 0 0 -0 0</pose>
          <geometry>
            <mesh>
              <scale>1 1 1</scale>
              <uri>/home/crp/git/quad_sys/src/a1_description/meshes/thigh_mirror.dae</uri>
            </mesh>
          </geometry>
          <material>
            <script>
              <name>Gazebo/DarkGrey</name>
              <uri>file://media/materials/scripts/gazebo.material</uri>
            </script>
          </material>
        </visual>
        <self_collide>1</self_collide>
        <enable_wind>0</enable_wind>
        <kinematic>0</kinematic>
      </link>
      <joint name='FR_calf_joint' type='revolute'>
        <pose relative_to='FR_thigh'>0 0 -0.2 0 -0 0</pose>
        <parent>FR_thigh</parent>
        <child>FR_calf</child>
        <axis>
          <xyz>0 1 0</xyz>
          <limit>
            <lower>-2.69653</lower>
            <upper>-0.916298</upper>
            <effort>33.5</effort>
            <velocity>21</velocity>
          </limit>
          <dynamics>
            <damping>0</damping>
            <friction>0</friction>
            <spring_reference>0</spring_reference>
            <spring_stiffness>0</spring_stiffness>
          </dynamics>
        </axis>
      </joint>
      <link name='FR_calf'>
        <pose relative_to='FR_calf_joint'>0 0 0 0 -0 0</pose>
        <inertial>
          <pose>0.005085 -0.000171 -0.126241 0 -0 0</pose>
          <mass>0.211</mass>
          <inertia>
            <ixx>0.00281049</ixx>
            <ixy>7.29135e-08</ixy>
            <ixz>-0.000172718</ixz>
            <iyy>0.00282865</iyy>
            <iyz>1.0577e-06</iyz>
            <izz>4.2928e-05</izz>
          </inertia>
        </inertial>
        <collision name='FR_calf_collision'>
          <pose>0 0 -0.1 3.14159 1.57079 3.14159</pose>
          <geometry>
            <box>
              <size>0.2 0.016 0.016</size>
            </box>
          </geometry>
          <surface>
            <contact>
              <ode/>
            </contact>
            <friction>
              <ode>
                <mu>0.2</mu>
                <mu2>0.2</mu2>
              </ode>
              <torsional>
                <ode/>
              </torsional>
            </friction>
            <bounce/>
          </surface>
          <max_contacts>10</max_contacts>
        </collision>
        <collision name='FR_calf_fixed_joint_lump__FR_foot_collision_1'>
          <pose>0 0 -0.2 0 -0 0</pose>
          <geometry>
            <sphere>
              <radius>0.02</radius>
            </sphere>
          </geometry>
          <surface>
            <contact>
              <ode>
                <kp>1e+06</kp>
                <kd>1</kd>
              </ode>
            </contact>
            <friction>
              <ode>
                <mu>0.6</mu>
                <mu2>0.6</mu2>
              </ode>
              <torsional>
                <ode/>
              </torsional>
            </friction>
            <bounce/>
          </surface>
          <max_contacts>10</max_contacts>
        </collision>
        <visual name='FR_calf_visual'>
          <pose>0 0 0 0 -0 0</pose>
          <geometry>
            <mesh>
              <scale>1 1 1</scale>
              <uri>/home/crp/git/quad_sys/src/a1_description/meshes/calf.dae</uri>
            </mesh>
          </geometry>
        </visual>
        <visual name='FR_calf_fixed_joint_lump__FR_foot_visual_1'>
          <pose>0 0 -0.2 0 -0 0</pose>
          <geometry>
            <sphere>
              <radius>0.01</radius>
            </sphere>
          </geometry>
          <plugin name='drawForcePlugin' filename='libunitreeDrawForcePlugin.so'>
            <topicName>FR_foot_contact</topicName>
            <robotNamespace>/</robotNamespace>
          </plugin>
          <material>
            <script>
              <name>Gazebo/DarkGrey</name>
              <uri>file://media/materials/scripts/gazebo.material</uri>
            </script>
          </material>
        </visual>
        <sensor name='FR_foot_contact' type='contact'>
          <update_rate>100</update_rate>
          <plugin name='contactPlugin' filename='libunitreeFootContactPlugin.so'>
            <robotNamespace>/</robotNamespace>
          </plugin>
          <contact>
            <collision>FR_calf_fixed_joint_lump__FR_foot_collision_1</collision>
            <topic>__default_topic__</topic>
          </contact>
        </sensor>
        <self_collide>1</self_collide>
        <self_collide>1</self_collide>
        <enable_wind>0</enable_wind>
        <kinematic>0</kinematic>
      </link>
      <joint name='RL_hip_joint' type='revolute'>
        <pose relative_to='base'>-0.1805 0.047 0 0 -0 0</pose>
        <parent>base</parent>
        <child>RL_hip</child>
        <axis>
          <xyz>1 0 0</xyz>
          <limit>
            <lower>-0.802851</lower>
            <upper>0.802851</upper>
            <effort>33.5</effort>
            <velocity>21</velocity>
          </limit>
          <dynamics>
            <damping>0</damping>
            <friction>0</friction>
            <spring_reference>0</spring_reference>
            <spring_stiffness>0</spring_stiffness>
          </dynamics>
        </axis>
      </joint>
      <link name='RL_hip'>
        <pose relative_to='RL_hip_joint'>0 0 0 0 -0 0</pose>
        <inertial>
          <pose>0.003875 0.001622 4.2e-05 0 -0 0</pose>
          <mass>0.595</mass>
          <inertia>
            <ixx>0.000402747</ixx>
            <ixy>8.709e-06</ixy>
            <ixz>2.97e-07</ixz>
            <iyy>0.000691123</iyy>
            <iyz>-5.45e-07</iyz>
            <izz>0.000487919</izz>
          </inertia>
        </inertial>
        <collision name='RL_hip_collision'>
          <pose>0 0 0 1.5708 -0 0</pose>
          <geometry>
            <cylinder>
              <length>0.04</length>
              <radius>0.046</radius>
            </cylinder>
          </geometry>
          <surface>
            <contact>
              <ode/>
            </contact>
            <friction>
              <ode>
                <mu>0.2</mu>
                <mu2>0.2</mu2>
              </ode>
              <torsional>
                <ode/>
              </torsional>
            </friction>
            <bounce/>
          </surface>
          <max_contacts>10</max_contacts>
        </collision>
        <collision name='RL_hip_fixed_joint_lump__RL_thigh_shoulder_collision_1'>
          <pose>0 0.081 0 1.5708 -0 0</pose>
          <geometry>
            <cylinder>
              <length>0.032</length>
              <radius>0.041</radius>
            </cylinder>
          </geometry>
          <max_contacts>10</max_contacts>
          <surface>
            <contact>
              <ode/>
            </contact>
            <bounce/>
            <friction>
              <torsional>
                <ode/>
              </torsional>
              <ode/>
            </friction>
          </surface>
        </collision>
        <visual name='RL_hip_visual'>
          <pose>0 0 0 3.14159 -0 3.14159</pose>
          <geometry>
            <mesh>
              <scale>1 1 1</scale>
              <uri>/home/crp/git/quad_sys/src/a1_description/meshes/hip.dae</uri>
            </mesh>
          </geometry>
          <material>
            <script>
              <name>Gazebo/DarkGrey</name>
              <uri>file://media/materials/scripts/gazebo.material</uri>
            </script>
          </material>
        </visual>
        <self_collide>0</self_collide>
        <enable_wind>0</enable_wind>
        <kinematic>0</kinematic>
      </link>
      <joint name='RL_thigh_joint' type='revolute'>
        <pose relative_to='RL_hip'>0 0.0838 0 0 -0 0</pose>
        <parent>RL_hip</parent>
        <child>RL_thigh</child>
        <axis>
          <xyz>0 1 0</xyz>
          <limit>
            <lower>-1.0472</lower>
            <upper>4.18879</upper>
            <effort>33.5</effort>
            <velocity>21</velocity>
          </limit>
          <dynamics>
            <damping>0</damping>
            <friction>0</friction>
            <spring_reference>0</spring_reference>
            <spring_stiffness>0</spring_stiffness>
          </dynamics>
        </axis>
      </joint>
      <link name='RL_thigh'>
        <pose relative_to='RL_thigh_joint'>0 0 0 0 -0 0</pose>
        <inertial>
          <pose>-0.003574 -0.019529 -0.030323 0 -0 0</pose>
          <mass>0.888</mass>
          <inertia>
            <ixx>0.00525181</ixx>
            <ixy>-2.168e-06</ixy>
            <ixz>0.000346889</ixz>
            <iyy>0.00500047</iyy>
            <iyz>-2.8174e-05</iyz>
            <izz>0.0011102</izz>
          </inertia>
        </inertial>
        <collision name='RL_thigh_collision'>
          <pose>0 0 -0.1 3.14159 1.57079 3.14159</pose>
          <geometry>
            <box>
              <size>0.2 0.0245 0.034</size>
            </box>
          </geometry>
          <surface>
            <contact>
              <ode>
                <kp>1e+06</kp>
                <kd>1</kd>
              </ode>
            </contact>
            <friction>
              <ode>
                <mu>0.2</mu>
                <mu2>0.2</mu2>
              </ode>
              <torsional>
                <ode/>
              </torsional>
            </friction>
            <bounce/>
          </surface>
          <max_contacts>10</max_contacts>
        </collision>
        <visual name='RL_thigh_visual'>
          <pose>0 0 0 0 -0 0</pose>
          <geometry>
            <mesh>
              <scale>1 1 1</scale>
              <uri>/home/crp/git/quad_sys/src/a1_description/meshes/thigh.dae</uri>
            </mesh>
          </geometry>
          <material>
            <script>
              <name>Gazebo/DarkGrey</name>
              <uri>file://media/materials/scripts/gazebo.material</uri>
            </script>
          </material>
        </visual>
        <self_collide>1</self_collide>
        <enable_wind>0</enable_wind>
        <kinematic>0</kinematic>
      </link>
      <joint name='RL_calf_joint' type='revolute'>
        <pose relative_to='RL_thigh'>0 0 -0.2 0 -0 0</pose>
        <parent>RL_thigh</parent>
        <child>RL_calf</child>
        <axis>
          <xyz>0 1 0</xyz>
          <limit>
            <lower>-2.69653</lower>
            <upper>-0.916298</upper>
            <effort>33.5</effort>
            <velocity>21</velocity>
          </limit>
          <dynamics>
            <damping>0</damping>
            <friction>0</friction>
            <spring_reference>0</spring_reference>
            <spring_stiffness>0</spring_stiffness>
          </dynamics>
        </axis>
      </joint>
      <link name='RL_calf'>
        <pose relative_to='RL_calf_joint'>0 0 0 0 -0 0</pose>
        <inertial>
          <pose>0.005085 -0.000171 -0.126241 0 -0 0</pose>
          <mass>0.211</mass>
          <inertia>
            <ixx>0.00281049</ixx>
            <ixy>7.29135e-08</ixy>
            <ixz>-0.000172718</ixz>
            <iyy>0.00282865</iyy>
            <iyz>1.0577e-06</iyz>
            <izz>4.2928e-05</izz>
          </inertia>
        </inertial>
        <collision name='RL_calf_collision'>
          <pose>0 0 -0.1 3.14159 1.57079 3.14159</pose>
          <geometry>
            <box>
              <size>0.2 0.016 0.016</size>
            </box>
          </geometry>
          <surface>
            <contact>
              <ode/>
            </contact>
            <friction>
              <ode>
                <mu>0.2</mu>
                <mu2>0.2</mu2>
              </ode>
              <torsional>
                <ode/>
              </torsional>
            </friction>
            <bounce/>
          </surface>
          <max_contacts>10</max_contacts>
        </collision>
        <collision name='RL_calf_fixed_joint_lump__RL_foot_collision_1'>
          <pose>0 0 -0.2 0 -0 0</pose>
          <geometry>
            <sphere>
              <radius>0.02</radius>
            </sphere>
          </geometry>
          <surface>
            <contact>
              <ode>
                <kp>1e+06</kp>
                <kd>1</kd>
              </ode>
            </contact>
            <friction>
              <ode>
                <mu>0.6</mu>
                <mu2>0.6</mu2>
              </ode>
              <torsional>
                <ode/>
              </torsional>
            </friction>
            <bounce/>
          </surface>
          <max_contacts>10</max_contacts>
        </collision>
        <visual name='RL_calf_visual'>
          <pose>0 0 0 0 -0 0</pose>
          <geometry>
            <mesh>
              <scale>1 1 1</scale>
              <uri>/home/crp/git/quad_sys/src/a1_description/meshes/calf.dae</uri>
            </mesh>
          </geometry>
        </visual>
        <visual name='RL_calf_fixed_joint_lump__RL_foot_visual_1'>
          <pose>0 0 -0.2 0 -0 0</pose>
          <geometry>
            <sphere>
              <radius>0.01</radius>
            </sphere>
          </geometry>
          <plugin name='drawForcePlugin' filename='libunitreeDrawForcePlugin.so'>
            <topicName>RL_foot_contact</topicName>
            <robotNamespace>/</robotNamespace>
          </plugin>
          <material>
            <script>
              <name>Gazebo/DarkGrey</name>
              <uri>file://media/materials/scripts/gazebo.material</uri>
            </script>
          </material>
        </visual>
        <sensor name='RL_foot_contact' type='contact'>
          <update_rate>100</update_rate>
          <plugin name='contactPlugin' filename='libunitreeFootContactPlugin.so'>
            <robotNamespace>/</robotNamespace>
          </plugin>
          <contact>
            <collision>RL_calf_fixed_joint_lump__RL_foot_collision_1</collision>
            <topic>__default_topic__</topic>
          </contact>
        </sensor>
        <self_collide>1</self_collide>
        <self_collide>1</self_collide>
        <enable_wind>0</enable_wind>
        <kinematic>0</kinematic>
      </link>
      <joint name='RR_hip_joint' type='revolute'>
        <pose relative_to='base'>-0.1805 -0.047 0 0 -0 0</pose>
        <parent>base</parent>
        <child>RR_hip</child>
        <axis>
          <xyz>1 0 0</xyz>
          <limit>
            <lower>-0.802851</lower>
            <upper>0.802851</upper>
            <effort>33.5</effort>
            <velocity>21</velocity>
          </limit>
          <dynamics>
            <damping>0</damping>
            <friction>0</friction>
            <spring_reference>0</spring_reference>
            <spring_stiffness>0</spring_stiffness>
          </dynamics>
        </axis>
      </joint>
      <link name='RR_hip'>
        <pose relative_to='RR_hip_joint'>0 0 0 0 -0 0</pose>
        <inertial>
          <pose>0.003875 -0.001622 4.2e-05 0 -0 0</pose>
          <mass>0.595</mass>
          <inertia>
            <ixx>0.000402747</ixx>
            <ixy>-8.709e-06</ixy>
            <ixz>2.97e-07</ixz>
            <iyy>0.000691123</iyy>
            <iyz>5.45e-07</iyz>
            <izz>0.000487919</izz>
          </inertia>
        </inertial>
        <collision name='RR_hip_collision'>
          <pose>0 0 0 1.5708 -0 0</pose>
          <geometry>
            <cylinder>
              <length>0.04</length>
              <radius>0.046</radius>
            </cylinder>
          </geometry>
          <surface>
            <contact>
              <ode/>
            </contact>
            <friction>
              <ode>
                <mu>0.2</mu>
                <mu2>0.2</mu2>
              </ode>
              <torsional>
                <ode/>
              </torsional>
            </friction>
            <bounce/>
          </surface>
          <max_contacts>10</max_contacts>
        </collision>
        <collision name='RR_hip_fixed_joint_lump__RR_thigh_shoulder_collision_1'>
          <pose>0 -0.081 0 1.5708 -0 0</pose>
          <geometry>
            <cylinder>
              <length>0.032</length>
              <radius>0.041</radius>
            </cylinder>
          </geometry>
          <max_contacts>10</max_contacts>
          <surface>
            <contact>
              <ode/>
            </contact>
            <bounce/>
            <friction>
              <torsional>
                <ode/>
              </torsional>
              <ode/>
            </friction>
          </surface>
        </collision>
        <visual name='RR_hip_visual'>
          <pose>0 0 0 0 -0 3.14159</pose>
          <geometry>
            <mesh>
              <scale>1 1 1</scale>
              <uri>/home/crp/git/quad_sys/src/a1_description/meshes/hip.dae</uri>
            </mesh>
          </geometry>
          <material>
            <script>
              <name>Gazebo/DarkGrey</name>
              <uri>file://media/materials/scripts/gazebo.material</uri>
            </script>
          </material>
        </visual>
        <self_collide>0</self_collide>
        <enable_wind>0</enable_wind>
        <kinematic>0</kinematic>
      </link>
      <joint name='RR_thigh_joint' type='revolute'>
        <pose relative_to='RR_hip'>0 -0.0838 0 0 -0 0</pose>
        <parent>RR_hip</parent>
        <child>RR_thigh</child>
        <axis>
          <xyz>0 1 0</xyz>
          <limit>
            <lower>-1.0472</lower>
            <upper>4.18879</upper>
            <effort>33.5</effort>
            <velocity>21</velocity>
          </limit>
          <dynamics>
            <damping>0</damping>
            <friction>0</friction>
            <spring_reference>0</spring_reference>
            <spring_stiffness>0</spring_stiffness>
          </dynamics>
        </axis>
      </joint>
      <link name='RR_thigh'>
        <pose relative_to='RR_thigh_joint'>0 0 0 0 -0 0</pose>
        <inertial>
          <pose>-0.003574 0.019529 -0.030323 0 -0 0</pose>
          <mass>0.888</mass>
          <inertia>
            <ixx>0.00525181</ixx>
            <ixy>2.168e-06</ixy>
            <ixz>0.000346889</ixz>
            <iyy>0.00500047</iyy>
            <iyz>2.8174e-05</iyz>
            <izz>0.0011102</izz>
          </inertia>
        </inertial>
        <collision name='RR_thigh_collision'>
          <pose>0 0 -0.1 3.14159 1.57079 3.14159</pose>
          <geometry>
            <box>
              <size>0.2 0.0245 0.034</size>
            </box>
          </geometry>
          <surface>
            <contact>
              <ode>
                <kp>1e+06</kp>
                <kd>1</kd>
              </ode>
            </contact>
            <friction>
              <ode>
                <mu>0.2</mu>
                <mu2>0.2</mu2>
              </ode>
              <torsional>
                <ode/>
              </torsional>
            </friction>
            <bounce/>
          </surface>
          <max_contacts>10</max_contacts>
        </collision>
        <visual name='RR_thigh_visual'>
          <pose>0 0 0 0 -0 0</pose>
          <geometry>
            <mesh>
              <scale>1 1 1</scale>
              <uri>/home/crp/git/quad_sys/src/a1_description/meshes/thigh_mirror.dae</uri>
            </mesh>
          </geometry>
          <material>
            <script>
              <name>Gazebo/DarkGrey</name>
              <uri>file://media/materials/scripts/gazebo.material</uri>
            </script>
          </material>
        </visual>
        <self_collide>1</self_collide>
        <enable_wind>0</enable_wind>
        <kinematic>0</kinematic>
      </link>
      <joint name='RR_calf_joint' type='revolute'>
        <pose relative_to='RR_thigh'>0 0 -0.2 0 -0 0</pose>
        <parent>RR_thigh</parent>
        <child>RR_calf</child>
        <axis>
          <xyz>0 1 0</xyz>
          <limit>
            <lower>-2.69653</lower>
            <upper>-0.916298</upper>
            <effort>33.5</effort>
            <velocity>21</velocity>
          </limit>
          <dynamics>
            <damping>0</damping>
            <friction>0</friction>
            <spring_reference>0</spring_reference>
            <spring_stiffness>0</spring_stiffness>
          </dynamics>
        </axis>
      </joint>
      <link name='RR_calf'>
        <pose relative_to='RR_calf_joint'>0 0 0 0 -0 0</pose>
        <inertial>
          <pose>0.005085 -0.000171 -0.126241 0 -0 0</pose>
          <mass>0.211</mass>
          <inertia>
            <ixx>0.00281049</ixx>
            <ixy>7.29135e-08</ixy>
            <ixz>-0.000172718</ixz>
            <iyy>0.00282865</iyy>
            <iyz>1.0577e-06</iyz>
            <izz>4.2928e-05</izz>
          </inertia>
        </inertial>
        <collision name='RR_calf_collision'>
          <pose>0 0 -0.1 3.14159 1.57079 3.14159</pose>
          <geometry>
            <box>
              <size>0.2 0.016 0.016</size>
            </box>
          </geometry>
          <surface>
            <contact>
              <ode/>
            </contact>
            <friction>
              <ode>
                <mu>0.2</mu>
                <mu2>0.2</mu2>
              </ode>
              <torsional>
                <ode/>
              </torsional>
            </friction>
            <bounce/>
          </surface>
          <max_contacts>10</max_contacts>
        </collision>
        <collision name='RR_calf_fixed_joint_lump__RR_foot_collision_1'>
          <pose>0 0 -0.2 0 -0 0</pose>
          <geometry>
            <sphere>
              <radius>0.02</radius>
            </sphere>
          </geometry>
          <surface>
            <contact>
              <ode>
                <kp>1e+06</kp>
                <kd>1</kd>
              </ode>
            </contact>
            <friction>
              <ode>
                <mu>0.6</mu>
                <mu2>0.6</mu2>
              </ode>
              <torsional>
                <ode/>
              </torsional>
            </friction>
            <bounce/>
          </surface>
          <max_contacts>10</max_contacts>
        </collision>
        <visual name='RR_calf_visual'>
          <pose>0 0 0 0 -0 0</pose>
          <geometry>
            <mesh>
              <scale>1 1 1</scale>
              <uri>/home/crp/git/quad_sys/src/a1_description/meshes/calf.dae</uri>
            </mesh>
          </geometry>
        </visual>
        <visual name='RR_calf_fixed_joint_lump__RR_foot_visual_1'>
          <pose>0 0 -0.2 0 -0 0</pose>
          <geometry>
            <sphere>
              <radius>0.01</radius>
            </sphere>
          </geometry>
          <plugin name='drawForcePlugin' filename='libunitreeDrawForcePlugin.so'>
            <topicName>RR_foot_contact</topicName>
            <robotNamespace>/</robotNamespace>
          </plugin>
          <material>
            <script>
              <name>Gazebo/DarkGrey</name>
              <uri>file://media/materials/scripts/gazebo.material</uri>
            </script>
          </material>
        </visual>
        <sensor name='RR_foot_contact' type='contact'>
          <update_rate>100</update_rate>
          <plugin name='contactPlugin' filename='libunitreeFootContactPlugin.so'>
            <robotNamespace>/</robotNamespace>
          </plugin>
          <contact>
            <collision>RR_calf_fixed_joint_lump__RR_foot_collision_1</collision>
            <topic>__default_topic__</topic>
          </contact>
        </sensor>
        <self_collide>1</self_collide>
        <self_collide>1</self_collide>
        <enable_wind>0</enable_wind>
        <kinematic>0</kinematic>
      </link>
      <plugin name='gazebo_ros_control' filename='libgazebo_ros_control.so'>
        <robotNamespace>/a1_gazebo</robotNamespace>
        <robotSimType>gazebo_ros_control/DefaultRobotHWSim</robotSimType>
      </plugin>
      <static>0</static>
      <plugin name='gazebo_ros_force' filename='libgazebo_ros_force.so'>
        <topicName>/apply_force/trunk</topicName>
        <robotNamespace>/</robotNamespace>
        <bodyName>base</bodyName>
        <xyzOffset>0 0 0</xyzOffset>
        <rpyOffset>0 -0 0</rpyOffset>
        <ignition::corrected_offsets>1</ignition::corrected_offsets>
      </plugin>
      <pose>0 0 0.6 0 -0 0</pose>
    </model>
    <model name='unit_box'>
      <link name='link'>
        <inertial>
          <mass>1</mass>
          <inertia>
            <ixx>0.166667</ixx>
            <ixy>0</ixy>
            <ixz>0</ixz>
            <iyy>0.166667</iyy>
            <iyz>0</iyz>
            <izz>0.166667</izz>
          </inertia>
          <pose>0 0 0 0 -0 0</pose>
        </inertial>
        <self_collide>0</self_collide>
        <enable_wind>0</enable_wind>
        <kinematic>0</kinematic>
        <pose>0 0 0 0 -0 0</pose>
        <gravity>1</gravity>
        <visual name='visual'>
          <geometry>
            <box>
              <size>2 2 2</size>
            </box>
          </geometry>
          <material>
            <script>
              <name>Gazebo/Grey</name>
              <uri>file://media/materials/scripts/gazebo.material</uri>
            </script>
            <shader type='pixel'>
              <normal_map>__default__</normal_map>
            </shader>
            <ambient>0.3 0.3 0.3 1</ambient>
            <diffuse>0.7 0.7 0.7 1</diffuse>
            <specular>0.01 0.01 0.01 1</specular>
            <emissive>0 0 0 1</emissive>
          </material>
          <pose>0 0 0 0 -0 0</pose>
          <transparency>0</transparency>
          <cast_shadows>1</cast_shadows>
        </visual>
        <collision name='collision'>
          <laser_retro>0</laser_retro>
          <max_contacts>10</max_contacts>
          <pose>0 0 0 0 -0 0</pose>
          <geometry>
            <box>
              <size>2 2 2</size>
            </box>
          </geometry>
          <surface>
            <friction>
              <ode>
                <mu>1</mu>
                <mu2>1</mu2>
                <fdir1>0 0 0</fdir1>
                <slip1>0</slip1>
                <slip2>0</slip2>
              </ode>
              <torsional>
                <coefficient>1</coefficient>
                <patch_radius>0</patch_radius>
                <surface_radius>0</surface_radius>
                <use_patch_radius>1</use_patch_radius>
                <ode>
                  <slip>0</slip>
                </ode>
              </torsional>
            </friction>
            <bounce>
              <restitution_coefficient>0</restitution_coefficient>
              <threshold>1e+06</threshold>
            </bounce>
            <contact>
              <collide_without_contact>0</collide_without_contact>
              <collide_without_contact_bitmask>1</collide_without_contact_bitmask>
              <collide_bitmask>1</collide_bitmask>
              <ode>
                <soft_cfm>0</soft_cfm>
                <soft_erp>0.2</soft_erp>
                <kp>1e+13</kp>
                <kd>1</kd>
                <max_vel>0.01</max_vel>
                <min_depth>0</min_depth>
              </ode>
              <bullet>
                <split_impulse>1</split_impulse>
                <split_impulse_penetration_threshold>-0.01</split_impulse_penetration_threshold>
                <soft_cfm>0</soft_cfm>
                <soft_erp>0.2</soft_erp>
                <kp>1e+13</kp>
                <kd>1</kd>
              </bullet>
            </contact>
          </surface>
        </collision>
      </link>
      <static>1</static>
      <allow_auto_disable>1</allow_auto_disable>
      <pose>1.09215 0.004722 -0.42 0 -0.15 0</pose>
    </model>
  </world>
</sdf>
